torch.Size([6, 288, 288])
Traceback (most recent call last):
  File "/home/david/miniconda3/envs/VQVAE/lib/python3.10/site-packages/PIL/Image.py", line 3311, in fromarray
    mode, rawmode = _fromarray_typemap[typekey]
KeyError: ((1, 1, 6), '|u1')

The above exception was the direct cause of the following exception:

Traceback (most recent call last):
  File "/home/david/Área de trabalho/projetos/NewVQVAE/Viewer.py", line 32, in <module>
    Viewer.saveTensorAsImg(data,"geral","trainImagens")
  File "/home/david/Área de trabalho/projetos/NewVQVAE/Viewer.py", line 11, in saveTensorAsImg
    name: wandb.Image(img, caption=caption)
  File "/home/david/miniconda3/envs/VQVAE/lib/python3.10/site-packages/wandb/sdk/data_types/image.py", line 179, in __init__
    self._initialize_from_data(data_or_path, mode, file_type)
  File "/home/david/miniconda3/envs/VQVAE/lib/python3.10/site-packages/wandb/sdk/data_types/image.py", line 315, in _initialize_from_data
    self._image = pil_image.fromarray(
  File "/home/david/miniconda3/envs/VQVAE/lib/python3.10/site-packages/PIL/Image.py", line 3315, in fromarray
    raise TypeError(msg) from e
TypeError: Cannot handle this data type: (1, 1, 6), |u1
Traceback (most recent call last):
  File "/home/david/miniconda3/envs/VQVAE/lib/python3.10/site-packages/PIL/Image.py", line 3311, in fromarray
    mode, rawmode = _fromarray_typemap[typekey]
KeyError: ((1, 1, 6), '|u1')

The above exception was the direct cause of the following exception:

Traceback (most recent call last):
  File "/home/david/Área de trabalho/projetos/NewVQVAE/Viewer.py", line 32, in <module>
    Viewer.saveTensorAsImg(data,"geral","trainImagens")
  File "/home/david/Área de trabalho/projetos/NewVQVAE/Viewer.py", line 11, in saveTensorAsImg
    name: wandb.Image(img, caption=caption)
  File "/home/david/miniconda3/envs/VQVAE/lib/python3.10/site-packages/wandb/sdk/data_types/image.py", line 179, in __init__
    self._initialize_from_data(data_or_path, mode, file_type)
  File "/home/david/miniconda3/envs/VQVAE/lib/python3.10/site-packages/wandb/sdk/data_types/image.py", line 315, in _initialize_from_data
    self._image = pil_image.fromarray(
  File "/home/david/miniconda3/envs/VQVAE/lib/python3.10/site-packages/PIL/Image.py", line 3315, in fromarray
    raise TypeError(msg) from e
TypeError: Cannot handle this data type: (1, 1, 6), |u1
